<?xml version='1.0'?>
<sdf version='1.7'>
  <model name='aerial'>
    <link name='quadcore'>
      <inertial>
        <pose>0.009579 -0.003349 -0.025285 0 -0 0</pose>
        <mass>5.2815</mass>
        <inertia>
          <ixx>0.022733</ixx>
          <ixy>-3.0215e-05</ixy>
          <ixz>2.666e-05</ixz>
          <iyy>0.022153</iyy>
          <iyz>-5.9394e-05</iyz>
          <izz>0.034666</izz>
        </inertia>
      </inertial>
      <collision name='quadcore_collision'>
        <pose>0 0 0 0 -0 0</pose>
        <geometry>
          <mesh>
            <scale>1 1 1</scale>
            <uri>model://aerial/URDF/meshes/quadcore.STL</uri>
          </mesh>
        </geometry>
        <surface>
          <contact>
            <ode/>
          </contact>
          <friction>
            <ode/>
          </friction>
        </surface>
      </collision>
      <visual name='quadcore_visual'>
        <pose>0 0 0 0 -0 0</pose>
        <geometry>
          <mesh>
            <scale>1 1 1</scale>
            <uri>model://aerial/URDF/meshes/quadcore.STL</uri>
          </mesh>
        </geometry>
        <material>
          <script>
            <name>Gazebo/Black</name>
            <uri>file://media/materials/scripts/gazebo.material</uri>
          </script>
        </material>
      </visual>
    </link>
    <joint name='backleftlink' type='revolute'>
      <pose relative_to='quadcore'>-0.33016 0.33017 0.067064 0 -0 0</pose>
      <parent>quadcore</parent>
      <child>backleft</child>
      <axis>
        <xyz>0.061628 -0.061629 0.99619</xyz>
        <limit>
          <lower>-1e+16</lower>
          <upper>1e+16</upper>
        </limit>
        <dynamics>
          <spring_reference>0</spring_reference>
          <spring_stiffness>0</spring_stiffness>
        </dynamics>
      </axis>
    </joint>
    <link name='backleft'>
      <pose relative_to='backleftlink'>0 0 0 0 -0 0</pose>
      <inertial>
        <pose>0.00231 -0.002311 0.037348 0 -0 0</pose>
        <mass>0.096653</mass>
        <inertia>
          <ixx>0.00015919</ixx>
          <ixy>-0.00042826</ixy>
          <ixz>5.3098e-05</ixz>
          <iyy>0.0012924</iyy>
          <iyz>1.7007e-05</iyz>
          <izz>0.0014435</izz>
        </inertia>
      </inertial>
      <collision name='backleft_collision'>
        <pose>0 0 0 0 -0 0</pose>
        <geometry>
          <mesh>
            <scale>1 1 1</scale>
            <uri>model://aerial/URDF/meshes/backleft.STL</uri>
          </mesh>
        </geometry>
        <surface>
          <contact>
            <ode/>
          </contact>
          <friction>
            <ode/>
          </friction>
        </surface>
      </collision>
      <visual name='backleft_visual'>
        <pose>0 0 0 0 -0 0</pose>
        <geometry>
          <mesh>
            <scale>1 1 1</scale>
            <uri>model://aerial/URDF/meshes/backleft.STL</uri>
          </mesh>
        </geometry>
        <material>
          <script>
            <name>Gazebo/Black</name>
            <uri>file://media/materials/scripts/gazebo.material</uri>
          </script>
        </material>
      </visual>
    </link>
    <joint name='backrightlink' type='revolute'>
      <pose relative_to='quadcore'>-0.33128 -0.33128 0.049128 0 -0 0</pose>
      <parent>quadcore</parent>
      <child>backright</child>
      <axis>
        <xyz>0.061628 0.061628 0.99619</xyz>
        <limit>
          <lower>-1e+16</lower>
          <upper>1e+16</upper>
        </limit>
        <dynamics>
          <spring_reference>0</spring_reference>
          <spring_stiffness>0</spring_stiffness>
        </dynamics>
      </axis>
    </joint>
    <link name='backright'>
      <pose relative_to='backrightlink'>0 0 0 0 -0 0</pose>
      <inertial>
        <pose>0.003428 0.003426 0.055386 0 -0 0</pose>
        <mass>0.096765</mass>
        <inertia>
          <ixx>1.9104e-05</ixx>
          <ixy>2.5228e-05</ixy>
          <ixz>8.6761e-05</ixz>
          <iyy>0.0014366</iyy>
          <iyz>-9.3025e-07</iyz>
          <izz>0.0014414</izz>
        </inertia>
      </inertial>
      <collision name='backright_collision'>
        <pose>0 0 0 0 -0 0</pose>
        <geometry>
          <mesh>
            <scale>1 1 1</scale>
            <uri>model://aerial/URDF/meshes/backright.STL</uri>
          </mesh>
        </geometry>
        <surface>
          <contact>
            <ode/>
          </contact>
          <friction>
            <ode/>
          </friction>
        </surface>
      </collision>
      <visual name='backright_visual'>
        <pose>0 0 0 0 -0 0</pose>
        <geometry>
          <mesh>
            <scale>1 1 1</scale>
            <uri>model://aerial/URDF/meshes/backright.STL</uri>
          </mesh>
        </geometry>
        <material>
          <script>
            <name>Gazebo/Black</name>
            <uri>file://media/materials/scripts/gazebo.material</uri>
          </script>
        </material>
      </visual>
    </link>
    <joint name='frontleftlink' type='revolute'>
      <pose relative_to='quadcore'>0.32872 0.32872 0.090436 0 -0 0</pose>
      <parent>quadcore</parent>
      <child>frontleft</child>
      <axis>
        <xyz>-0.061629 -0.061628 0.99619</xyz>
        <limit>
          <lower>-1e+16</lower>
          <upper>1e+16</upper>
        </limit>
        <dynamics>
          <spring_reference>0</spring_reference>
          <spring_stiffness>0</spring_stiffness>
        </dynamics>
      </axis>
    </joint>
    <link name='frontleft'>
      <pose relative_to='frontleftlink'>0 0 0 0 -0 0</pose>
      <inertial>
        <pose>-0.000865 -0.000865 0.013977 0 -0 0</pose>
        <mass>0.096713</mass>
        <inertia>
          <ixx>0.00041278</ixx>
          <ixy>-0.00063121</ixy>
          <ixz>-0.000103</ixz>
          <iyy>0.0010477</iyy>
          <iyz>-6.3724e-05</iyz>
          <izz>0.0014362</izz>
        </inertia>
      </inertial>
      <collision name='frontleft_collision'>
        <pose>0 0 0 0 -0 0</pose>
        <geometry>
          <mesh>
            <scale>1 1 1</scale>
            <uri>model://aerial/URDF/meshes/frontleft.STL</uri>
          </mesh>
        </geometry>
        <surface>
          <contact>
            <ode/>
          </contact>
          <friction>
            <ode/>
          </friction>
        </surface>
      </collision>
      <visual name='frontleft_visual'>
        <pose>0 0 0 0 -0 0</pose>
        <geometry>
          <mesh>
            <scale>1 1 1</scale>
            <uri>model://aerial/URDF/meshes/frontleft.STL</uri>
          </mesh>
        </geometry>
        <material>
          <script>
            <name>Gazebo/Black</name>
            <uri>file://media/materials/scripts/gazebo.material</uri>
          </script>
        </material>
      </visual>
    </link>
    <joint name='frontrightlink' type='revolute'>
      <pose relative_to='quadcore'>0.32947 -0.32948 0.078321 0 -0 0</pose>
      <parent>quadcore</parent>
      <child>frontright</child>
      <axis>
        <xyz>-0.061628 0.061629 0.99619</xyz>
        <limit>
          <lower>-1e+16</lower>
          <upper>1e+16</upper>
        </limit>
        <dynamics>
          <spring_reference>0</spring_reference>
          <spring_stiffness>0</spring_stiffness>
        </dynamics>
      </axis>
    </joint>
    <link name='frontright'>
      <pose relative_to='frontrightlink'>0 0 0 0 -0 0</pose>
      <inertial>
        <pose>-0.00162 0.00162 0.026192 0 -0 0</pose>
        <mass>0.096663</mass>
        <inertia>
          <ixx>9.7821e-05</ixx>
          <ixy>0.00032002</ixy>
          <ixz>-0.00010319</ixz>
          <iyy>0.0013595</iyy>
          <iyz>2.5135e-05</iyz>
          <izz>0.0014378</izz>
        </inertia>
      </inertial>
      <collision name='frontright_collision'>
        <pose>0 0 0 0 -0 0</pose>
        <geometry>
          <mesh>
            <scale>1 1 1</scale>
            <uri>model://aerial/URDF/meshes/frontright.STL</uri>
          </mesh>
        </geometry>
        <surface>
          <contact>
            <ode/>
          </contact>
          <friction>
            <ode/>
          </friction>
        </surface>
      </collision>
      <visual name='frontright_visual'>
        <pose>0 0 0 0 -0 0</pose>
        <geometry>
          <mesh>
            <scale>1 1 1</scale>
            <uri>model://aerial/URDF/meshes/frontright.STL</uri>
          </mesh>
        </geometry>
        <material>
          <script>
            <name>Gazebo/Black</name>
            <uri>file://media/materials/scripts/gazebo.material</uri>
          </script>
        </material>
      </visual>
    </link>
    <joint name='quadcore/ground_truth/odometry_sensorgt_joint' type='revolute'>
      <pose relative_to='quadcore'>0 0 0 0 -0 0</pose>
      <parent>quadcore</parent>
      <child>quadcore/ground_truth/odometry_sensorgt_link</child>
      <axis>
        <xyz>0 0 1</xyz>
        <limit>
          <lower>-1e+16</lower>
          <upper>1e+16</upper>
        </limit>
        <dynamics>
          <spring_reference>0</spring_reference>
          <spring_stiffness>0</spring_stiffness>
        </dynamics>
      </axis>
    </joint>
    <link name='quadcore/ground_truth/odometry_sensorgt_link'>
      <pose relative_to='quadcore/ground_truth/odometry_sensorgt_joint'>0 0 0 0 -0 0</pose>
      <inertial>
        <pose>0 0 0 0 -0 0</pose>
        <mass>0.0015</mass>
        <inertia>
          <ixx>0.0001</ixx>
          <ixy>0</ixy>
          <ixz>0</ixz>
          <iyy>0.0002</iyy>
          <iyz>0</iyz>
          <izz>0.0002</izz>
        </inertia>
      </inertial>
    </link>
    <joint name='quadcore/imu_joint' type='revolute'>
      <pose relative_to='quadcore'>0 0 0 0 -0 0</pose>
      <parent>quadcore</parent>
      <child>quadcore/imu_link</child>
      <axis>
        <xyz>0 0 1</xyz>
        <limit>
          <lower>-1e+16</lower>
          <upper>1e+16</upper>
        </limit>
        <dynamics>
          <spring_reference>0</spring_reference>
          <spring_stiffness>0</spring_stiffness>
        </dynamics>
      </axis>
    </joint>
    <link name='quadcore/imu_link'>
      <pose relative_to='quadcore/imu_joint'>0 0 0 0 -0 0</pose>
      <inertial>
        <pose>0 0 0 0 -0 0</pose>
        <mass>0.0015</mass>
        <inertia>
          <ixx>1e-05</ixx>
          <ixy>0</ixy>
          <ixz>0</ixz>
          <iyy>2e-05</iyy>
          <iyz>0</iyz>
          <izz>2e-05</izz>
        </inertia>
      </inertial>
    </link>
    <static>0</static>
    <plugin name='arducopter_plugin' filename='libArduPilotPlugin.so'>
      <fdm_addr>127.0.0.1</fdm_addr>
      <fdm_port_in>9002</fdm_port_in>
      <fdm_port_out>9003</fdm_port_out>
      <modelXYZToAirplaneXForwardZDown>0 0 0 3.141593 0 0</modelXYZToAirplaneXForwardZDown>
      <gazeboXYZToNED>0 0 0 3.141593 0 0</gazeboXYZToNED>
      <imuName>quadcore::quadcore/imu_link::imu_sensor</imuName>
      <connectionTimeoutMaxCount>5</connectionTimeoutMaxCount>
      <control channel='0'>
        <type>VELOCITY</type>
        <offset>0</offset>
        <p_gain>0.20</p_gain>
        <i_gain>0</i_gain>
        <d_gain>0</d_gain>
        <i_max>0</i_max>
        <i_min>0</i_min>
        <cmd_max>2.5</cmd_max>
        <cmd_min>-2.5</cmd_min>
        <jointName>quadcore::frontright</jointName>
        <multiplier>838</multiplier>
        <controlVelocitySlowdownSim>1</controlVelocitySlowdownSim>
      </control>
      <control channel='1'>
        <type>VELOCITY</type>
        <offset>0</offset>
        <p_gain>0.20</p_gain>
        <i_gain>0</i_gain>
        <d_gain>0</d_gain>
        <i_max>0</i_max>
        <i_min>0</i_min>
        <cmd_max>2.5</cmd_max>
        <cmd_min>-2.5</cmd_min>
        <jointName>quadcore::frontleft</jointName>
        <multiplier>838</multiplier>
        <controlVelocitySlowdownSim>1</controlVelocitySlowdownSim>
      </control>
      <control channel='2'>
        <type>VELOCITY</type>
        <offset>0</offset>
        <p_gain>0.20</p_gain>
        <i_gain>0</i_gain>
        <d_gain>0</d_gain>
        <i_max>0</i_max>
        <i_min>0</i_min>
        <cmd_max>2.5</cmd_max>
        <cmd_min>-2.5</cmd_min>
        <jointName>quadcore::backleft</jointName>
        <multiplier>-838</multiplier>
        <controlVelocitySlowdownSim>1</controlVelocitySlowdownSim>
      </control>
      <control channel='3'>
        <type>VELOCITY</type>
        <offset>0</offset>
        <p_gain>0.20</p_gain>
        <i_gain>0</i_gain>
        <d_gain>0</d_gain>
        <i_max>0</i_max>
        <i_min>0</i_min>
        <cmd_max>2.5</cmd_max>
        <cmd_min>-2.5</cmd_min>
        <jointName>quadcore::backright</jointName>
        <multiplier>-838</multiplier>
        <controlVelocitySlowdownSim>1</controlVelocitySlowdownSim>
      </control>
    </plugin>
  </model>
</sdf>
